cat: /etc/redhat-release: No such file or directory
test_0 (__main__.lab1a.test_0)
[Lab 1] - [Investigation 3] - [Part 2] - printing - Test for file creation: ./lab1a.py ... ok
test_a (__main__.lab1a.test_a)
[Lab 1] - [Investigation 3] - [Part 2] - printing - Test for errors running: ./lab1a.py ... /usr/lib/python3.12/subprocess.py:822: ResourceWarning: unclosed file <_io.TextIOWrapper name=3 encoding='UTF-8'>
  _cleanup()
ResourceWarning: Enable tracemalloc to get the object allocation traceback
ok
test_a1 (__main__.lab1a.test_a1)
[Lab 1] - [Investigation 3] - [Part 2] - printing - Test for correct shebang line: ./lab1a.py ... FAIL

======================================================================
FAIL: test_a1 (__main__.lab1a.test_a1)
[Lab 1] - [Investigation 3] - [Part 2] - printing - Test for correct shebang line: ./lab1a.py
----------------------------------------------------------------------
Traceback (most recent call last):
  File "/home/ivan/lab1-demo/./CheckLab1.py", line 79, in test_a1
    self.assertEqual(first_line, '#!/usr/bin/env python3\n', msg=error_output)
AssertionError: '' != '#!/usr/bin/env python3\n'
+ #!/usr/bin/env python3
 : your program does not have a shebang line(HINT: what should the first line contain)

----------------------------------------------------------------------
Ran 3 tests in 0.017s

FAILED (failures=1)
OPS435 Lab Report - System Information for running ./CheckLab1.py
=================================================================
    User login name: ivan
    Linux system name: ivan-VirtualBox
    Linux system version: 
    Python executable: /usr/bin/python3
    Python version: 3123
    OS Platform: linux
    Working Directory: /home/ivan/lab1-demo
    Start at: Fri May 17 17:08:29 2024
=================================================================
